Workbook

Sheet Rec.Data System-IN
B4: LAPORAN KEUANGAN | AB4: ü
B5: GMAHK KONFERENS JAKARTA & SEKITARNYA | AB5: û
B6: Jl. Dr Saharjo 48 Jakarta Selatan
B7: Telp : 021 - 8370 6855 - 856, 829 2976, Fax 021 - 829 4278
B10: Nama Jemaat : | D10: KIWI | S10: Tahun : | T10: 2024
B12: No | C12: Bulan | D12: No. Kwitansi | F12: CR No. | G12: TGL | H12: DANA MISSION SEDUNIA | N12: Transfer ke Konferens DKI | R12: DANA JEMAAT
D13: Awal | E13: Akhir | H13: Total Konferens | I13: Perpuluhan | J13: Unit X | K13: 50% Terpadu Konfrens | L13: Unit PT | M13: Persembahan Khusus | N13: 611100 ( Tithe ) | O13: 634110 (One Off) | P13: 678110(Miscell) | Q13: Total | R13: 50% Terpadu Jemaat | S13: Persembahan Khusus | T13: Penginjilan | U13: Pembangunan | V13: Pendidikan | W13: Lain - Lain
B16: 1 | C16: Januari | D16: KIW01/24/0001 | E16: KIW01/24/0050 | F16: 4941-1 | G16: 45323 | H16: =I16+K16+M16 -> 36495122 | I16: 34388577 | J16: 49 | K16: 2106545 | L16: 23 | N16: 34388577 | O16: 2106545 | Q16: =N16+O16+P16 -> 36495122 | R16: 2106545 | S16: 4509222 | T16: 100000 | U16: 277751 | V16: 100000 | W16: 2400000
B17: 2 | C17: Februari | D17: KIW01/24/0153 | E17: KIW01/24/0218 | F17: 5279-1 | G17: 45358 | H17: =I17+K17+M17 -> 73893942 | I17: 69280726 | J17: 50 | K17: 4613216 | L17: 21 | N17: 69280726 | O17: 4613216 | Q17: =N17+O17+P17 -> 73893942 | R17: 4613216 | S17: 36074547 | T17: 27380000 | U17: 3552500 | V17: 2581000 | W17: 3058000
B18: 3 | C18: Maret | D18: KIW01/24/0219 | E18: KIW01/24/0289 | F18: 5517-1 | G18: 45382 | H18: =I18+K18+M18 -> 63128929 | I18: 61231814 | J18: 58 | K18: 1897115 | L18: 19 | N18: 61231814 | O18: 1897115 | Q18: =N18+O18+P18 -> 63128929 | R18: 1897115 | S18: 24397399 | T18: 33034000 | U18: 1345000 | V18: 732000 | W18: 5085040
B19: 4 | C19: April | D19: KIW01/24/0290 | E19: KIW01/24/0352 | F19: 5779-1 | G19: 45411 | H19: =I19+K19+M19 -> 63670859 | I19: 62082393 | J19: 47 | K19: 1588466 | L19: 19 | N19: 62082393 | O19: 1588466 | Q19: =N19+O19+P19 -> 63670859 | R19: 1588466 | S19: 21310816 | T19: 1100000 | U19: 16039795 | V19: 600000 | W19: 2648120
B20: 5 | C20: Mei | D20: KIW01/24/0353 | E20: KIW01/24/0418 | F20: 6125-1 | G20: 45442 | H20: =I20+K20+M20 -> 39684532 | I20: 37687853 | J20: 49 | K20: 1996679 | L20: 19 | N20: 37687853 | O20: 1996679 | Q20: =N20+O20+P20 -> 39684532 | R20: 1996679 | S20: 10217270 | T20: 3900000 | U20: 32466000 | V20: 350000 | W20: 5729000
B21: 6 | C21: Juni | D21: KIW01/24/0419 | E21: KIW01/24/0493 | F21: 6491-1 | G21: 45468 | H21: =I21+K21+M21 -> 61483678 | I21: 59067101 | J21: 55 | K21: 2416577 | L21: 22 | N21: 59067101 | O21: 2416577 | Q21: =N21+O21+P21 -> 61483678 | R21: 2416577 | S21: 16426150 | T21: 590000 | U21: 69316843 | V21: 667000 | W21: 4460000
B22: 7 | C22: Juli | D22: KIW01/24/0494 | E22: KIW01/24/0564 | F22: 6722-1 | G22: 45509 | H22: =I22+K22+M22 -> 59838782 | I22: 58319968 | J22: 48 | K22: 1518814 | L22: 17 | N22: 58319968 | O22: 1518814 | Q22: =N22+O22+P22 -> 59838782 | R22: 1518814 | S22: 19074884 | U22: 34021000 | V22: 1178000 | W22: 5772000
B23: 8 | C23: Agustus | D23: KIW01/24/0565 | E23: KIW01/24/0637 | F23: 7171-1 | G23: 45544 | H23: =I23+K23+M23 -> 97945981 | I23: 96035088 | J23: 66 | K23: 1910893 | L23: 19 | N23: 96035088 | O23: 1910893 | Q23: =N23+O23+P23 -> 97945981 | R23: 1910893 | S23: 11439387 | U23: 32181077 | V23: 859000 | W23: 46114923
B24: 9 | C24: September | D24: KIW01/24/0638 | E24: KIW01/24/0704 | F24: 7499-1 | G24: 45566 | H24: =I24+K24+M24 -> 43324762 | I24: 41951324 | J24: 49 | K24: 1373438 | L24: 12 | N24: 41951324 | O24: 1373438 | Q24: =N24+O24+P24 -> 43324762 | R24: 1373438 | S24: 22111795 | U24: 148842875 | V24: 834000 | W24: 61702137
B25: 10 | C25: Oktober | D25: KIW01/24/0705 | E25: KIW01/24/0780 | F25: 7593.7741 | G25: 45596 | H25: =I25+K25+M25 -> 127961789 | I25: 126324735 | J25: 56 | K25: 1637054 | L25: 19 | N25: 126324735 | O25: 1637054 | Q25: =N25+O25+P25 -> 127961789 | R25: 1637054 | S25: 66742440 | U25: 79000 | V25: 1856000 | W25: 18141313
B26: 11 | C26: November | D26: KIW01/24/0781 | E26: KIW01/24/0851 | F26: 7983-1 | G26: 45627 | H26: =I26+K26+M26 -> 88775691 | I26: 86984175 | J26: 53 | K26: 1791516 | L26: 18 | N26: 86984175 | O26: 1791516 | Q26: =N26+O26+P26 -> 88775691 | R26: 1791516 | S26: 25668172 | U26: 125000 | V26: 728000 | W26: 72422145
B27: 12 | C27: Desember | D27: KIW01/24/0852 | E27: KIW01/24/0925 | F27: 8198-1 | G27: 45655 | H27: =I27+K27+M27 -> 48647552 | I27: 47101210 | J27: 53 | K27: 1546342 | L27: 17 | N27: 47101210 | O27: 1546342 | Q27: =N27+O27+P27 -> 48647552 | R27: 1546342 | S27: 61304315 | U27: 2358122 | V27: 640000 | W27: 7825000
Q28: =SUM(Q16:Q27) -> 804851619
D29: Jumlah Perpuluhan / Persembahan | G29: Total | H29: =SUM(H16:H27) -> 804851619 | I29: =SUM(I14:I27) -> 780454964 | K29: =SUM(K14:K27) -> 24396655 | M29: =SUM(M14:M27) -> 0 | N29: =SUM(N16:N28) -> 780454964 | O29: =SUM(O16:O27) -> 24396655 | P29: =SUM(P16:P27) -> 0 | Q29: =IF(N29=I29,"Sama","Kurang Bayar") -> Sama | R29: =SUM(R14:R27) -> 24396655 | S29: =SUM(S14:S27) -> 319276397 | T29: =SUM(T14:T27) -> 66104000 | U29: =SUM(U14:U27) -> 340604963 | V29: =SUM(V14:V27) -> 11125000 | W29: =SUM(W14:W27) -> 235357678
G30: Unit Pemberi | J30: =SUM(J16:J27) -> 633 | L30: =SUM(L16:L27) -> 225 | Q30: =IF(O29+P29=K29+M29,"Sama","Kurang Bayar") -> Sama
Q33: =I29-N29 -> 0
C34: Gembala | D34: Pdt.Hasiholan Sihombing (Pdt.Falmer Sagala) | Q34: =K29-O29 -> 0
C35: Bendahara | D35: Sari Samosir | Q35: =M29-P29 -> 0
C36: Wilayah | D36: VII | Q36: =SUM(Q33:Q35) -> 0
C37: No HP/TLP | D37: 0813 7147 0915

Sheet Rec. Data System-Out
B2: OPERATING INCOME AND OPERATING EXPENSE
B4: ITEMS | H4: TOTAL EXPENSE
C5: Dana - Operasional | E5: =H48+H114+H190+H263+H328+H400+H467+H538+H611+H690+H766+H850 -> 324952410 | H5: =SUM(E5:E9) -> 985183540
C6: Dana - Penginjilan | E6: =H53+H119+H197+H268+H333+H405+H472+H543+H616+H695+H771+H855 -> 66104000
C7: Dana - Pembangunan | E7: =H58+H124+H202+H273+H338+H410+H477+H548+H621+H700+H776+H860 -> 338013452
C8: Dana - Pendidikan | E8: =H63+H129+H207+H278+H343+H415+H482+H553+H626+H705+H781+H865 -> 11125000
C9: Dana - Lain-lain | E9: =H68+H134+H212+H283+H348+H421+H487+H558+H634+H711+H788+H877 -> 244988678
B11: PERIOD: | E11: 45292 | H11: 45657
E12: FROM | H12: TO
B16: ='Rec.Data System-IN'!D10 -> KIWI
B17: OPERATING INCOME AND OPERATING EXPENSE
B18: JANUARY
C20: Operating Income : | M20: Ketua Jemaat
M21: Sekertaris Jemaat
C22: Dana Jemaat | F22: Saldo Awal | H22: Penerimaan | I22: Total | M22: Bendahara Jemaat
M23: Depart Sekolah Sabat
C24: Terpadu | H24: ='Rec.Data System-IN'!R16 -> 2106545 | I24: =F24+H24 -> 2106545 | M24: Depart Pel. Perorangan
C25: Khusus Jemaat 100% | H25: ='Rec.Data System-IN'!S16 -> 4509222 | I25: =F25+H25 -> 4509222 | M25: Departement Anak Anak
C26: Dana Operasional | F26: 22925600 | H26: =SUM(H24:H25) -> 6615767 | I26: =F26+H26 -> 29541367 | M26: Departement BWA & Shepherdes
C27: Penginjilan | F27: 0 | H27: ='Rec.Data System-IN'!T16 -> 100000 | I27: =F27+H27 -> 100000 | M27: Departement Penatalayanan
C28: Pembangunan | F28: 0 | H28: ='Rec.Data System-IN'!U16 -> 277751 | I28: =F28+H28 -> 277751 | M28: Departement Dorkas
C29: Pendidikan | F29: 0 | H29: ='Rec.Data System-IN'!V16 -> 100000 | I29: =F29+H29 -> 100000 | M29: Departement Pemuda ( PA )
C30: Lain - Lain | F30: 9631000 | H30: ='Rec.Data System-IN'!W16 -> 2400000 | I30: =F30+H30 -> 12031000 | M30: Pathfinder
M31: Departement Pendidikan
C32: Total Operating Income | I32: =SUM(I26:I30) -> 42050118 | M32: Departement Rumah Tangga
M33: Departement Komunikasi
C34: Operating Expense : | M34: Departement Kesehatan
M35: Departement NDR/Pel. Masarakat
C36: Keterangan | E36: No Transaksi | F36: Departemen | M36: Diakon
F37: Sumber Kas | M37: Diakones
M38: Perlawatan, Pel. Sosial & Charity
B39: 1 | C39: Sosialisasi Umkm -transport | E39: KIW01/2024/0001 | F39: Operational | H39: 250000 | M39: Buku SS Dewasa
B40: 2 | C40: Rawat Inap - Agus Damanik & Ibu Rosni | E40: KIW01/2024/0002 | F40: Operational | H40: 500000 | M40: Buku SS Anak - Anak / Remaja
B41: 3 | C41: Operasional Rutin - Listrik, Kostur Etc | E41: KIW01/2024/0003 | F41: Operational | H41: 8735693
B42: 4 | C42: Pp-ss Cabang Bojongsari | E42: KIW01/2024/0006 | F42: Operational | H42: 2171000
B43: 5 | C43: Air Minum | E43: KIW01/2024/0007 | F43: Operational | H43: 352000
B44: 6 | C44: Fotocopy Kertas Acara | E44: KIW01/2024/0008 | F44: Operational | H44: 174000 | M44: Buku WGA
B45: 7 | C45: Gift-ultah &amp; Apresiasi | E45: KIW01/2024/0009 | F45: Operational | H45: 4002500 | M45: Perkemahan Anak-Anak & Pemuda
B46: 8 | C46: Gift-apresiasi Pekan Doa Ssa | E46: KIW01/2024/0010 | F46: Operational | H46: 1000000 | M46: Kebaktian Kebangunan Rohani ( KKR )
B47: 9 | C47: Advance Payment - Bojong, Beras | E47: KIW01/2024/0011 | F47: Operational | H47: 1300000 | M47: KPA (Kel. Kecil) & Pemeliharaan
...

Sheet Rekap T&O
B2: REKAPITULASI KEUANGAN GEREJA - GEREJA
B3: GMAHK KONFERENS JAKARTA DAN SEKITARNYA
B4: TAHUN 2024
B6: X / T | C6: No. Kwitansi | F6: CR No. | G6: X (Perpul) | H6: Terpadu Konf | I6: Khusus Konf | J6: Terpadu Jemaat | K6: Khusus Jemaat | L6: Penginjilan | M6: Pembangunan | N6: Pendidikan | O6: Lain - Lain | P6: Unit X | Q6: Unit PT
B7: Januari | C7: ='Rec.Data System-IN'!D16 -> KIW01/24/0001 | D7: s/d | E7: ='Rec.Data System-IN'!E16 -> KIW01/24/0050 | F7: ='Rec.Data System-IN'!F16 -> 4941-1 | G7: ='Rec.Data System-IN'!I16 -> 34388577 | H7: ='Rec.Data System-IN'!K16 -> 2106545 | I7: ='Rec.Data System-IN'!M16 -> 0 | J7: ='Rec.Data System-IN'!R16 -> 2106545 | K7: ='Rec.Data System-IN'!S16 -> 4509222 | L7: ='Rec.Data System-IN'!T16 -> 100000 | M7: ='Rec.Data System-IN'!U16 -> 277751 | N7: ='Rec.Data System-IN'!V16 -> 100000 | O7: ='Rec.Data System-IN'!W16 -> 2400000 | P7: ='Rec.Data System-IN'!J16 -> 49 | Q7: ='Rec.Data System-IN'!L16 -> 23
B8: Februari | C8: ='Rec.Data System-IN'!D17 -> KIW01/24/0153 | D8: s/d | E8: ='Rec.Data System-IN'!E17 -> KIW01/24/0218 | F8: ='Rec.Data System-IN'!F17 -> 5279-1 | G8: ='Rec.Data System-IN'!I17 -> 69280726 | H8: ='Rec.Data System-IN'!K17 -> 4613216 | I8: ='Rec.Data System-IN'!M17 -> 0 | J8: ='Rec.Data System-IN'!R17 -> 4613216 | K8: ='Rec.Data System-IN'!S17 -> 36074547 | L8: ='Rec.Data System-IN'!T17 -> 27380000 | M8: ='Rec.Data System-IN'!U17 -> 3552500 | N8: ='Rec.Data System-IN'!V17 -> 2581000 | O8: ='Rec.Data System-IN'!W17 -> 3058000 | P8: ='Rec.Data System-IN'!J17 -> 50 | Q8: ='Rec.Data System-IN'!L17 -> 21
B9: Maret | C9: ='Rec.Data System-IN'!D18 -> KIW01/24/0219 | D9: s/d | E9: ='Rec.Data System-IN'!E18 -> KIW01/24/0289 | F9: ='Rec.Data System-IN'!F18 -> 5517-1 | G9: ='Rec.Data System-IN'!I18 -> 61231814 | H9: ='Rec.Data System-IN'!K18 -> 1897115 | I9: ='Rec.Data System-IN'!M18 -> 0 | J9: ='Rec.Data System-IN'!R18 -> 1897115 | K9: ='Rec.Data System-IN'!S18 -> 24397399 | L9: ='Rec.Data System-IN'!T18 -> 33034000 | M9: ='Rec.Data System-IN'!U18 -> 1345000 | N9: ='Rec.Data System-IN'!V18 -> 732000 | O9: ='Rec.Data System-IN'!W18 -> 5085040 | P9: ='Rec.Data System-IN'!J18 -> 58 | Q9: ='Rec.Data System-IN'!L18 -> 19
B10: April | C10: ='Rec.Data System-IN'!D19 -> KIW01/24/0290 | D10: s/d | E10: ='Rec.Data System-IN'!E19 -> KIW01/24/0352 | F10: ='Rec.Data System-IN'!F19 -> 5779-1 | G10: ='Rec.Data System-IN'!I19 -> 62082393 | H10: ='Rec.Data System-IN'!K19 -> 1588466 | I10: ='Rec.Data System-IN'!M19 -> 0 | J10: ='Rec.Data System-IN'!R19 -> 1588466 | K10: ='Rec.Data System-IN'!S19 -> 21310816 | L10: ='Rec.Data System-IN'!T19 -> 1100000 | M10: ='Rec.Data System-IN'!U19 -> 16039795 | N10: ='Rec.Data System-IN'!V19 -> 600000 | O10: ='Rec.Data System-IN'!W19 -> 2648120 | P10: ='Rec.Data System-IN'!J19 -> 47 | Q10: ='Rec.Data System-IN'!L19 -> 19
B11: Mei | C11: ='Rec.Data System-IN'!D20 -> KIW01/24/0353 | D11: s/d | E11: ='Rec.Data System-IN'!E20 -> KIW01/24/0418 | F11: ='Rec.Data System-IN'!F20 -> 6125-1 | G11: ='Rec.Data System-IN'!I20 -> 37687853 | H11: ='Rec.Data System-IN'!K20 -> 1996679 | I11: ='Rec.Data System-IN'!M20 -> 0 | J11: ='Rec.Data System-IN'!R20 -> 1996679 | K11: ='Rec.Data System-IN'!S20 -> 10217270 | L11: ='Rec.Data System-IN'!T20 -> 3900000 | M11: ='Rec.Data System-IN'!U20 -> 32466000 | N11: ='Rec.Data System-IN'!V20 -> 350000 | O11: ='Rec.Data System-IN'!W20 -> 5729000 | P11: ='Rec.Data System-IN'!J20 -> 49 | Q11: ='Rec.Data System-IN'!L20 -> 19
B12: Juni | C12: ='Rec.Data System-IN'!D21 -> KIW01/24/0419 | D12: s/d | E12: ='Rec.Data System-IN'!E21 -> KIW01/24/0493 | F12: ='Rec.Data System-IN'!F21 -> 6491-1 | G12: ='Rec.Data System-IN'!I21 -> 59067101 | H12: ='Rec.Data System-IN'!K21 -> 2416577 | I12: ='Rec.Data System-IN'!M21 -> 0 | J12: ='Rec.Data System-IN'!R21 -> 2416577 | K12: ='Rec.Data System-IN'!S21 -> 16426150 | L12: ='Rec.Data System-IN'!T21 -> 590000 | M12: ='Rec.Data System-IN'!U21 -> 69316843 | N12: ='Rec.Data System-IN'!V21 -> 667000 | O12: ='Rec.Data System-IN'!W21 -> 4460000 | P12: ='Rec.Data System-IN'!J21 -> 55 | Q12: ='Rec.Data System-IN'!L21 -> 22
B13: Juli | C13: ='Rec.Data System-IN'!D22 -> KIW01/24/0494 | D13: s/d | E13: ='Rec.Data System-IN'!E22 -> KIW01/24/0564 | F13: ='Rec.Data System-IN'!F22 -> 6722-1 | G13: ='Rec.Data System-IN'!I22 -> 58319968 | H13: ='Rec.Data System-IN'!K22 -> 1518814 | I13: ='Rec.Data System-IN'!M22 -> 0 | J13: ='Rec.Data System-IN'!R22 -> 1518814 | K13: ='Rec.Data System-IN'!S22 -> 19074884 | L13: ='Rec.Data System-IN'!T22 -> 0 | M13: ='Rec.Data System-IN'!U22 -> 34021000 | N13: ='Rec.Data System-IN'!V22 -> 1178000 | O13: ='Rec.Data System-IN'!W22 -> 5772000 | P13: ='Rec.Data System-IN'!J22 -> 48 | Q13: ='Rec.Data System-IN'!L22 -> 17
B14: Agustus | C14: ='Rec.Data System-IN'!D23 -> KIW01/24/0565 | D14: s/d | E14: ='Rec.Data System-IN'!E23 -> KIW01/24/0637 | F14: ='Rec.Data System-IN'!F23 -> 7171-1 | G14: ='Rec.Data System-IN'!I23 -> 96035088 | H14: ='Rec.Data System-IN'!K23 -> 1910893 | I14: ='Rec.Data System-IN'!M23 -> 0 | J14: ='Rec.Data System-IN'!R23 -> 1910893 | K14: ='Rec.Data System-IN'!S23 -> 11439387 | L14: ='Rec.Data System-IN'!T23 -> 0 | M14: ='Rec.Data System-IN'!U23 -> 32181077 | N14: ='Rec.Data System-IN'!V23 -> 859000 | O14: ='Rec.Data System-IN'!W23 -> 46114923 | P14: ='Rec.Data System-IN'!J23 -> 66 | Q14: ='Rec.Data System-IN'!L23 -> 19
B15: September | C15: ='Rec.Data System-IN'!D24 -> KIW01/24/0638 | D15: s/d | E15: ='Rec.Data System-IN'!E24 -> KIW01/24/0704 | F15: ='Rec.Data System-IN'!F24 -> 7499-1 | G15: ='Rec.Data System-IN'!I24 -> 41951324 | H15: ='Rec.Data System-IN'!K24 -> 1373438 | I15: ='Rec.Data System-IN'!M24 -> 0 | J15: ='Rec.Data System-IN'!R24 -> 1373438 | K15: ='Rec.Data System-IN'!S24 -> 22111795 | L15: ='Rec.Data System-IN'!T24 -> 0 | M15: ='Rec.Data System-IN'!U24 -> 148842875 | N15: ='Rec.Data System-IN'!V24 -> 834000 | O15: ='Rec.Data System-IN'!W24 -> 61702137 | P15: ='Rec.Data System-IN'!J24 -> 49 | Q15: ='Rec.Data System-IN'!L24 -> 12
B16: Oktober | C16: ='Rec.Data System-IN'!D25 -> KIW01/24/0705 | D16: s/d | E16: ='Rec.Data System-IN'!E25 -> KIW01/24/0780 | F16: ='Rec.Data System-IN'!F25 -> 7593.7741 | G16: ='Rec.Data System-IN'!I25 -> 126324735 | H16: ='Rec.Data System-IN'!K25 -> 1637054 | I16: ='Rec.Data System-IN'!M25 -> 0 | J16: ='Rec.Data System-IN'!R25 -> 1637054 | K16: ='Rec.Data System-IN'!S25 -> 66742440 | L16: ='Rec.Data System-IN'!T25 -> 0 | M16: ='Rec.Data System-IN'!U25 -> 79000 | N16: ='Rec.Data System-IN'!V25 -> 1856000 | O16: ='Rec.Data System-IN'!W25 -> 18141313 | P16: ='Rec.Data System-IN'!J25 -> 56 | Q16: ='Rec.Data System-IN'!L25 -> 19
B17: November | C17: ='Rec.Data System-IN'!D26 -> KIW01/24/0781 | D17: s/d | E17: ='Rec.Data System-IN'!E26 -> KIW01/24/0851 | F17: ='Rec.Data System-IN'!F26 -> 7983-1 | G17: ='Rec.Data System-IN'!I26 -> 86984175 | H17: ='Rec.Data System-IN'!K26 -> 1791516 | I17: ='Rec.Data System-IN'!M26 -> 0 | J17: ='Rec.Data System-IN'!R26 -> 1791516 | K17: ='Rec.Data System-IN'!S26 -> 25668172 | L17: ='Rec.Data System-IN'!T26 -> 0 | M17: ='Rec.Data System-IN'!U26 -> 125000 | N17: ='Rec.Data System-IN'!V26 -> 728000 | O17: ='Rec.Data System-IN'!W26 -> 72422145 | P17: ='Rec.Data System-IN'!J26 -> 53 | Q17: ='Rec.Data System-IN'!L26 -> 18
B18: Desember | C18: ='Rec.Data System-IN'!D27 -> KIW01/24/0852 | D18: s/d | E18: ='Rec.Data System-IN'!E27 -> KIW01/24/0925 | F18: ='Rec.Data System-IN'!F27 -> 8198-1 | G18: ='Rec.Data System-IN'!I27 -> 47101210 | H18: ='Rec.Data System-IN'!K27 -> 1546342 | I18: ='Rec.Data System-IN'!M27 -> 0 | J18: ='Rec.Data System-IN'!R27 -> 1546342 | K18: ='Rec.Data System-IN'!S27 -> 61304315 | L18: ='Rec.Data System-IN'!T27 -> 0 | M18: ='Rec.Data System-IN'!U27 -> 2358122 | N18: ='Rec.Data System-IN'!V27 -> 640000 | O18: ='Rec.Data System-IN'!W27 -> 7825000 | P18: ='Rec.Data System-IN'!J27 -> 53 | Q18: ='Rec.Data System-IN'!L27 -> 17
B19: TOTAL | G19: =SUM(G7:G18) -> 780454964 | H19: =SUM(H7:H18) -> 24396655 | I19: =SUM(I7:I18) -> 0 | J19: =SUM(J7:J18) -> 24396655 | K19: =SUM(K7:K18) -> 319276397 | L19: =SUM(L7:L18) -> 66104000 | M19: =SUM(M7:M18) -> 340604963 | N19: =SUM(N7:N18) -> 11125000 | ... Q19: =SUM(Q7:Q18) -> 225
C21: Gereja | E21: ='Rec.Data System-IN'!D10 -> KIWI
C22: Gembala | E22: ='Rec.Data System-IN'!D34 -> Pdt.Hasiholan Sihombing (Pdt.Falmer Sagala)
C23: Bendahara | E23: ='Rec.Data System-IN'!D35 -> Sari Samosir
C24: Wilayah | E24: ='Rec.Data System-IN'!D36 -> VII

Sheet Detail Shedules
B1: ='Rec.Data System-IN'!D10 -> KIWI
B3: DETAIL SHEDULES
B4: ='Rec.Data System-IN'!T10 -> 2024
B6: Comparison of Budget VS Tithe & Offering | C6: Actual 2024 | E6: Budget 2024 | G6: In(De)crease | I6: Percentage
B7: Tithe | C7: ='Rec.Data System-IN'!N29 -> 780454964 | E7: 657258622 | G7: =C7-E7 -> 123196342 | I7: =G7/C7 -> 0.15785196
B8: Terpadu 50% | C8: ='Rec.Data System-IN'!O29 -> 24396655 | E8: 11098953 | G8: =C8-E8 -> 13297702 | I8: =G8/C8 -> 0.54506251
B10: Total Budget vs Tithe & Offering | C10: =SUM(C7:C9) -> 804851619 | D10: =SUM(D7:D9) -> 0 | E10: =SUM(E7:E9) -> 668357575 | F10: =SUM(F7:F9) -> 0 | G10: =SUM(G7:G9) -> 136494044 | H10: =SUM(H7:H9) -> 0 | I10: =G10/C10 -> 0.16958908
B12: Increment Tithe & Offering : | C12: Actual 2023 | E12: Actual 2024 | G12: In(De)crease | I12: Percentage
B14: Tithe | C14: 574069841 | E14: ='Rec.Data System-IN'!N29 -> 780454964 | G14: =E14-C14 -> 206385123 | I14: =G14/C14 -> 0.35951222
B15: Terpadu 50% | C15: 19650647 | E15: ='Rec.Data System-IN'!O29 -> 24396655 | G15: =E15-C15 -> 4746008 | I15: =G15/C15 -> 0.24151917
B16: Khusus Konferens | C16: 0 | E16: ='Rec.Data System-IN'!P29 -> 0 | G16: =E16-C16 -> 0
B17: Total Increment Tithe & Offering | C17: =SUM(C14:C16) -> 593720488 | E17: =SUM(E14:E16) -> 804851619 | G17: =SUM(G14:G16) -> 211131131 | I17: =G17/C17 -> 0.35560695
B19: Increment Giving Unit : | C19: Actual 2023 | E19: Actual 2024 | G19: In(De)crease | I19: Percentage
B20: Members Active Church: 187
B21: Tithe | C21: 630 | E21: ='Rekap T&O'!P19 -> 633 | G21: =E21-C21 -> 3 | I21: =G21/C21 -> 0.0047619048
B22: Terpadu 50% | C22: 205 | E22: ='Rekap T&O'!Q19 -> 225 | G22: =E22-C22 -> 20 | I22: =G22/C22 -> 0.097560976
B23: Total Increment Giving unit | C23: =SUM(C21:C22) -> 835 | E23: =SUM(E21:E22) -> 858 | G23: =SUM(G21:G22) -> 23 | I23: =G23/C23 -> 0.02754491
B26: Perbandingan Penerimaan Dana Jemaat: | C26: Actual 2023 | E26: Actual 2024 | G26: In(De)crease | I26: Percentage
B28: Terpadu 50% | C28: 19650647 | E28: ='Rec.Data System-IN'!R29 -> 24396655 | G28: =E28-C28 -> 4746008 | I28: =G28/C28 -> 0.24151917
B29: Khusus Jemaat | C29: 96281749 | E29: ='Rec.Data System-IN'!S29 -> 319276397 | G29: =E29-C29 -> 222994648 | I29: =G29/C29 -> 2.3160635
B30: Dana Penginjilan | C30: 120001 | E30: ='Rec.Data System-IN'!T29 -> 66104000 | G30: =E30-C30 -> 65983999 | I30: =G30/C30 -> 549.86208
B31: Dana Pembangunan | C31: 3670000 | E31: ='Rec.Data System-IN'!U29 -> 340604963 | G31: =E31-C31 -> 336934963 | I31: =G31/C31 -> 91.807892
B32: Dana Pendidikan | C32: 4683518 | E32: ='Rec.Data System-IN'!V29 -> 11125000 | G32: =E32-C32 -> 6441482 | I32: =G32/C32 -> 1.3753512
B33: Dana Lain Lain | C33: 29408000 | E33: ='Rec.Data System-IN'!W29 -> 235357678 | G33: =E33-C33 -> 205949678 | I33: =G33/C33 -> 7.0031855
B35: Penerimaan Dana Jemaat | C35: =SUM(C28:C34) -> 153813915 | D35: =SUM(D28:D34) -> 0 | E35: ='Rec.Data System-IN'!R29+'Rec.Data System-IN'!S29+'Rec.Data System-IN'!T29+'Rec.Data System-IN'!U29+'Rec.Data System-IN'!V29+'Rec.Data System-IN'!W29 -> 996864693 | F35: =SUM(F28:F34) -> 0 | G35: =E35-C35 -> 843050778 | I35: =G35/C35 -> 5.4809786
B37: Perbandingan Pengeluaran Dana Jemaat : | C37: Actual 2023 | E37: Actual 2024 | G37: In(De)crease | I37: Percentage
B39: Dana Operasional | C39: 111847921 | E39: ='Rec. Data System-Out'!H48+'Rec. Data System-Out'!H114+'Rec. Data System-Out'!H190+'Rec. Data System-Out'!H263+'Rec. Data System-Out'!H328+'Rec. Data System-Out'!H400+'Rec. Data System-Out'!H467+'Rec. Data System-Out'!H538+'Rec. Data System-Out'!H611+'Rec. Data System-Out'!H690+'Rec. Data System-Out'!H766+'Rec. Data System-Out'!H850 -> 324952410 | G39: =E39-C39 -> 213104489 | I39: =G39/C39 -> 1.9053058
B40: Dana Penginjilan | C40: 120001 | E40: ='Rec. Data System-Out'!H53+'Rec. Data System-Out'!H119+'Rec. Data System-Out'!H197+'Rec. Data System-Out'!H268+'Rec. Data System-Out'!H333+'Rec. Data System-Out'!H405+'Rec. Data System-Out'!H472+'Rec. Data System-Out'!H543+'Rec. Data System-Out'!H616+'Rec. Data System-Out'!H695+'Rec. Data System-Out'!H771+'Rec. Data System-Out'!H855 -> 66104000 | G40: =E40-C40 -> 65983999 | I40: =G40/C40 -> 549.86208
B41: Dana Pembangunan | C41: 3670000 | E41: ='Rec. Data System-Out'!H58+'Rec. Data System-Out'!H124+'Rec. Data System-Out'!H202+'Rec. Data System-Out'!H273+'Rec. Data System-Out'!H338+'Rec. Data System-Out'!H410+'Rec. Data System-Out'!H477+'Rec. Data System-Out'!H548+'Rec. Data System-Out'!H621+'Rec. Data System-Out'!H700+'Rec. Data System-Out'!H776+'Rec. Data System-Out'!H860 -> 338013452 | G41: =E41-C41 -> 334343452 | I41: =G41/C41 -> 91.101758
B42: Dana Pendidikan | C42: 6908518 | E42: ='Rec. Data System-Out'!H63+'Rec. Data System-Out'!H129+'Rec. Data System-Out'!H207+'Rec. Data System-Out'!H278+'Rec. Data System-Out'!H343+'Rec. Data System-Out'!H415+'Rec. Data System-Out'!H482+'Rec. Data System-Out'!H553+'Rec. Data System-Out'!H626+'Rec. Data System-Out'!H705+'Rec. Data System-Out'!H781+'Rec. Data System-Out'!H865 -> 11125000 | G42: =E42-C42 -> 4216482 | I42: =G42/C42 -> 0.6103309
B43: Dana Lain Lain | C43: 29408000 | E43: ='Rec. Data System-Out'!H68+'Rec. Data System-Out'!H134+'Rec. Data System-Out'!H212+'Rec. Data System-Out'!H283+'Rec. Data System-Out'!H348+'Rec. Data System-Out'!H421+'Rec. Data System-Out'!H487+'Rec. Data System-Out'!H558+'Rec. Data System-Out'!H634+'Rec. Data System-Out'!H711+'Rec. Data System-Out'!H788+'Rec. Data System-Out'!H877 -> 244988678 | G43: =E43-C43 -> 215580678 | I43: =G43/C43 -> 7.3306814
B45: Pengeluaran Dana Jemaat | C45: =SUM(C39:C44) -> 151954440 | E45: ='Rec. Data System-Out'!H70+'Rec. Data System-Out'!H136+'Rec. Data System-Out'!H214+'Rec. Data System-Out'!H285+'Rec. Data System-Out'!H350+'Rec. Data System-Out'!H423+'Rec. Data System-Out'!H489+'Rec. Data System-Out'!H560+'Rec. Data System-Out'!H636+'Rec. Data System-Out'!H713+'Rec. Data System-Out'!H790+'Rec. Data System-Out'!H879 -> 985183540 | G45: =E45-C45 -> 833229100 | I45: =G45/C45 -> 5.483414
C48: Balance | I48: Balance
B49: Trust Funds : | C49: Jan 1, 2024 | E49: Received | G49: Remitted | I49: Dec 31, 2024
B50: Tithe | C50: 0 | E50: ='Rec.Data System-IN'!I29 -> 780454964 | G50: ='Rec.Data System-IN'!N29 -> 780454964 | I50: =C50+E50-G50 -> 0
B51: Terpadu 50% & Khusus Konferens | C51: 0 | E51: ='Rec.Data System-IN'!K29+'Rec.Data System-IN'!M29 -> 24396655 | G51: ='Rec.Data System-IN'!O29+'Rec.Data System-IN'!P29 -> 24396655 | I51: =C51+E51-G51 -> 0
B52: Dana Jemaat | C52: ='Rec. Data System-Out'!F26+'Rec. Data System-Out'!F27+'Rec. Data System-Out'!F28+'Rec. Data System-Out'!F29+'Rec. Data System-Out'!F30 -> 32556600 | E52: ='Rekap T&O'!J19+'Rekap T&O'!K19+'Rekap T&O'!L19+'Rekap T&O'!M19+'Rekap T&O'!N19+'Rekap T&O'!O19 -> 996864693 | G52: ='Rec. Data System-Out'!H70+'Rec. Data System-Out'!H136+'Rec. Data System-Out'!H214+'Rec. Data System-Out'!H285+'Rec. Data System-Out'!H350+'Rec. Data System-Out'!H423+'Rec. Data System-Out'!H489+'Rec. Data System-Out'!H560+'Rec. Data System-Out'!H636+'Rec. Data System-Out'!H713+'Rec. Data System-Out'!H790+'Rec. Data System-Out'!H879 -> 985183540 | I52: =C52+E52-G52 -> 44237753
B54: Total Trust Funds | I54: =SUM(I50:I53) -> 44237753

Sheet Ringkasan
B2: LAPORAN KAS JEMAAT 2024
B4: No | C4: Keterangan | D4: Penerimaan Dana Jemaat | I4: Pengeluaran | J4: Saldo Akhir
D5: Dana Operasional | E5: Dana Penginjilan | F5: Dana Pembangunan | G5: Dana Pendidikan | H5: Dana Lain - Lain
B7: 1 | C7: Januari | D7: ='Rec.Data System-IN'!R16+'Rec.Data System-IN'!S16+'Rec. Data System-Out'!F26 -> 29541367 | E7: ='Rec.Data System-IN'!T16+'Rec. Data System-Out'!F27 -> 100000 | F7: ='Rec.Data System-IN'!U16+'Rec. Data System-Out'!F28 -> 277751 | G7: ='Rec.Data System-IN'!V16+'Rec. Data System-Out'!F29 -> 100000 | H7: ='Rec.Data System-IN'!W16+'Rec. Data System-Out'!F30 -> 12031000 | I7: ='Rec. Data System-Out'!H70 -> 22262693 | J7: =D7+E7+F7+G7+H7-I7 -> 19787425
B8: 2 | C8: Februari | D8: ='Rec.Data System-IN'!R17+'Rec.Data System-IN'!S17 -> 40687763 | E8: ='Rec.Data System-IN'!T17 -> 27380000 | F8: ='Rec.Data System-IN'!U17 -> 3552500 | G8: ='Rec.Data System-IN'!V17 -> 2581000 | H8: ='Rec.Data System-IN'!W17 -> 3058000 | I8: ='Rec. Data System-Out'!H136 -> 51828687 | J8: =D8+E8+F8+G8+H8-I8 -> 25430576
B9: 3 | C9: Maret | D9: ='Rec.Data System-IN'!R18+'Rec.Data System-IN'!S18 -> 26294514 | E9: ='Rec.Data System-IN'!T18 -> 33034000 | F9: ='Rec.Data System-IN'!U18 -> 1345000 | G9: ='Rec.Data System-IN'!V18 -> 732000 | H9: ='Rec.Data System-IN'!W18 -> 5085040 | I9: ='Rec. Data System-Out'!H214 -> 66017697 | J9: =D9+E9+F9+G9+H9-I9 -> 472857
B10: 4 | C10: April | D10: ='Rec.Data System-IN'!R19+'Rec.Data System-IN'!S19 -> 22899282 | E10: ='Rec.Data System-IN'!T19 -> 1100000 | F10: ='Rec.Data System-IN'!U19 -> 16039795 | G10: ='Rec.Data System-IN'!V19 -> 600000 | H10: ='Rec.Data System-IN'!W19 -> 2648120 | I10: ='Rec. Data System-Out'!H285 -> 53337003 | J10: =D10+E10+F10+G10+H10-I10 -> -10049806
B11: 5 | C11: Mei | D11: ='Rec.Data System-IN'!R20+'Rec.Data System-IN'!S20 -> 12213949 | E11: ='Rec.Data System-IN'!T20 -> 3900000 | F11: ='Rec.Data System-IN'!U20 -> 32466000 | G11: ='Rec.Data System-IN'!V20 -> 350000 | H11: ='Rec.Data System-IN'!W20 -> 5729000 | I11: ='Rec. Data System-Out'!H350 -> 52290906 | J11: =D11+E11+F11+G11+H11-I11 -> 2368043
B12: 6 | C12: June | D12: ='Rec.Data System-IN'!R21+'Rec.Data System-IN'!S21 -> 18842727 | E12: ='Rec.Data System-IN'!T21 -> 590000 | F12: ='Rec.Data System-IN'!U21 -> 69316843 | G12: ='Rec.Data System-IN'!V21 -> 667000 | H12: ='Rec.Data System-IN'!W21 -> 4460000 | I12: ='Rec. Data System-Out'!H423 -> 89789162 | J12: =D12+E12+F12+G12+H12-I12 -> 4087408
B13: 7 | C13: Juli | D13: ='Rec.Data System-IN'!R22+'Rec.Data System-IN'!S22 -> 20593698 | E13: ='Rec.Data System-IN'!T22 -> 0 | F13: ='Rec.Data System-IN'!U22 -> 34021000 | G13: ='Rec.Data System-IN'!V22 -> 1178000 | H13: ='Rec.Data System-IN'!W22 -> 5772000 | I13: ='Rec. Data System-Out'!H489 -> 65030846 | J13: =D13+E13+F13+G13+H13-I13 -> -3466148
B14: 8 | C14: Agustus | D14: ='Rec.Data System-IN'!R23+'Rec.Data System-IN'!S23 -> 13350280 | E14: ='Rec.Data System-IN'!T23 -> 0 | F14: ='Rec.Data System-IN'!U23 -> 32181077 | G14: ='Rec.Data System-IN'!V23 -> 859000 | H14: ='Rec.Data System-IN'!W23 -> 46114923 | I14: ='Rec. Data System-Out'!H560 -> 43612952 | J14: =D14+E14+F14+G14+H14-I14 -> 48892328
B15: 9 | C15: September | D15: ='Rec.Data System-IN'!R24+'Rec.Data System-IN'!S24 -> 23485233 | E15: ='Rec.Data System-IN'!T24 -> 0 | F15: ='Rec.Data System-IN'!U24 -> 148842875 | G15: ='Rec.Data System-IN'!V24 -> 834000 | H15: ='Rec.Data System-IN'!W24 -> 61702137 | I15: ='Rec. Data System-Out'!H636 -> 289191322 | J15: =D15+E15+F15+G15+H15-I15 -> -54327077
B16: 10 | C16: Oktober | D16: ='Rec.Data System-IN'!R25+'Rec.Data System-IN'!S25 -> 68379494 | E16: ='Rec.Data System-IN'!T25 -> 0 | F16: ='Rec.Data System-IN'!U25 -> 79000 | G16: ='Rec.Data System-IN'!V25 -> 1856000 | H16: ='Rec.Data System-IN'!W25 -> 18141313 | I16: ='Rec. Data System-Out'!H713 -> 67738416 | J16: =D16+E16+F16+G16+H16-I16 -> 20717391
B17: 11 | C17: November | D17: ='Rec.Data System-IN'!R26+'Rec.Data System-IN'!S26 -> 27459688 | E17: ='Rec.Data System-IN'!T26 -> 0 | F17: ='Rec.Data System-IN'!U26 -> 125000 | G17: ='Rec.Data System-IN'!V26 -> 728000 | H17: ='Rec.Data System-IN'!W26 -> 72422145 | I17: ='Rec. Data System-Out'!H790 -> 96376433 | J17: =D17+E17+F17+G17+H17-I17 -> 4358400
B18: 12 | C18: Desember | D18: ='Rec.Data System-IN'!R27+'Rec.Data System-IN'!S27 -> 62850657 | E18: ='Rec.Data System-IN'!T27 -> 0 | F18: ='Rec.Data System-IN'!U27 -> 2358122 | G18: ='Rec.Data System-IN'!V27 -> 640000 | H18: ='Rec.Data System-IN'!W27 -> 7825000 | I18: ='Rec. Data System-Out'!H879 -> 87707423 | J18: =D18+E18+F18+G18+H18-I18 -> -14033644
C19: TOTAL Dana Jemaat | D19: =SUM(D7:D18) -> 366598652 | E19: =SUM(E7:E18) -> 66104000 | F19: =SUM(F7:F18) -> 340604963 | G19: =SUM(G7:G18) -> 11125000 | H19: =SUM(H7:H18) -> 244988678 | I19: =SUM(I7:I18) -> 985183540 | J19: =SUM(J7:J18) -> 44237753
B22: LAPORAN DANA KONFERENS 2024
B24: No | C24: Keterangan | D24: Dana Konferens | G24: Total Dana | H24: Transfer ke Konf | I24: Saldo Akhir
D25: Perpuluhan | E25: Terpadu ( 50% ) | F25: Dana Khusus Konf
B27: 1 | C27: Januari | D27: ='Rec.Data System-IN'!I16 -> 34388577 | E27: ='Rec.Data System-IN'!K16 -> 2106545 | F27: ='Rec.Data System-IN'!M16 -> 0 | G27: =D27+E27+F27 -> 36495122 | H27: ='Rec.Data System-IN'!Q16 -> 36495122 | I27: =G27-H27 -> 0
B28: 2 | C28: Februari | D28: ='Rec.Data System-IN'!I17 -> 69280726 | E28: ='Rec.Data System-IN'!K17 -> 4613216 | F28: ='Rec.Data System-IN'!M17 -> 0 | G28: =D28+E28+F28 -> 73893942 | H28: ='Rec.Data System-IN'!Q17 -> 73893942 | I28: =G28-H28 -> 0
B29: 3 | C29: Maret | D29: ='Rec.Data System-IN'!I18 -> 61231814 | E29: ='Rec.Data System-IN'!K18 -> 1897115 | F29: ='Rec.Data System-IN'!M18 -> 0 | G29: =D29+E29+F29 -> 63128929 | H29: ='Rec.Data System-IN'!Q18 -> 63128929 | I29: =G29-H29 -> 0
B30: 4 | C30: April | D30: ='Rec.Data System-IN'!I19 -> 62082393 | E30: ='Rec.Data System-IN'!K19 -> 1588466 | F30: ='Rec.Data System-IN'!M19 -> 0 | G30: =D30+E30+F30 -> 63670859 | H30: ='Rec.Data System-IN'!Q19 -> 63670859 | I30: =G30-H30 -> 0
B31: 5 | C31: Mei | D31: ='Rec.Data System-IN'!I20 -> 37687853 | E31: ='Rec.Data System-IN'!K20 -> 1996679 | F31: ='Rec.Data System-IN'!M20 -> 0 | G31: =D31+E31+F31 -> 39684532 | H31: ='Rec.Data System-IN'!Q20 -> 39684532 | I31: =G31-H31 -> 0
B32: 6 | C32: June | D32: ='Rec.Data System-IN'!I21 -> 59067101 | E32: ='Rec.Data System-IN'!K21 -> 2416577 | F32: ='Rec.Data System-IN'!M21 -> 0 | G32: =D32+E32+F32 -> 61483678 | H32: ='Rec.Data System-IN'!Q21 -> 61483678 | I32: =G32-H32 -> 0
B33: 7 | C33: Juli | D33: ='Rec.Data System-IN'!I22 -> 58319968 | E33: ='Rec.Data System-IN'!K22 -> 1518814 | F33: ='Rec.Data System-IN'!M22 -> 0 | G33: =D33+E33+F33 -> 59838782 | H33: ='Rec.Data System-IN'!Q22 -> 59838782 | I33: =G33-H33 -> 0
B34: 8 | C34: Agustus | D34: ='Rec.Data System-IN'!I23 -> 96035088 | E34: ='Rec.Data System-IN'!K23 -> 1910893 | F34: ='Rec.Data System-IN'!M23 -> 0 | G34: =D34+E34+F34 -> 97945981 | H34: ='Rec.Data System-IN'!Q23 -> 97945981 | I34: =G34-H34 -> 0
B35: 9 | C35: September | D35: ='Rec.Data System-IN'!I24 -> 41951324 | E35: ='Rec.Data System-IN'!K24 -> 1373438 | F35: ='Rec.Data System-IN'!M24 -> 0 | G35: =D35+E35+F35 -> 43324762 | H35: ='Rec.Data System-IN'!Q24 -> 43324762 | I35: =G35-H35 -> 0
B36: 10 | C36: Oktober | D36: ='Rec.Data System-IN'!I25 -> 126324735 | E36: ='Rec.Data System-IN'!K25 -> 1637054 | F36: ='Rec.Data System-IN'!M25 -> 0 | G36: =D36+E36+F36 -> 127961789 | H36: ='Rec.Data System-IN'!Q25 -> 127961789 | I36: =G36-H36 -> 0
B37: 11 | C37: November | D37: ='Rec.Data System-IN'!I26 -> 86984175 | E37: ='Rec.Data System-IN'!K26 -> 1791516 | F37: ='Rec.Data System-IN'!M26 -> 0 | G37: =D37+E37+F37 -> 88775691 | H37: ='Rec.Data System-IN'!Q26 -> 88775691 | I37: =G37-H37 -> 0
B38: 12 | C38: Desember | D38: ='Rec.Data System-IN'!I27 -> 47101210 | E38: ='Rec.Data System-IN'!K27 -> 1546342 | F38: ='Rec.Data System-IN'!M27 -> 0 | G38: =D38+E38+F38 -> 48647552 | H38: ='Rec.Data System-IN'!Q27 -> 48647552 | I38: =G38-H38 -> 0
C39: TOTAL Dana Konfrens | D39: =SUM(D27:D38) -> 780454964 | E39: =SUM(E27:E38) -> 24396655 | F39: =SUM(F27:F38) -> 0 | G39: =SUM(G27:G38) -> 804851619 | H39: =SUM(H27:H38) -> 804851619 | I39: =SUM(I27:I38) -> 0

Sheet Anjuran & Masukan
B2: AUDIT REPORT
B3: Anjuran dan Masukan untuk dapat di Jalankan Bendahara Jemaat
B8: 1 | C8: Kami Ucapkan Trimakasih kepada Bendahara Jemaat atas mengirimkan / Transfer ke Konferens sesuai dengan Laporan Keuangan Jemaat (Balance)
C9: Perpuluhan Rp. 0
C10: Persembahan Terpadu Rp. 0
C11: Khusus Konferens Rp. 0
C13: Kami Ucapkan Trimakasih adanya Peningkatan Persentasi Persepuluhan dan Persembahan Terpadu tahun 2024 bandingkan tahun 2023 yaitu : 35,56 %
B15: =B8+1 -> 2 | C15: Kami Ucapkan Trimakasih atas Laporan Pengeluaran Jemaat komplit di ikutsertakan dalam Pengiriman Laporan Keuangan Jemaat.
C16: Saldo Akhir Desember 2024, Laporan Kas Jemaat Rp. 44 237 753,-
B18: =B15+1 -> 3 | C18: Kami Meminta agar Pdt Jemaat dan Bendahara JEMAAT KIWI Untuk memeriksa / Checking Laporan Kas jemaat Desember 2024
C19: Sejumlah Rp. 44 237 753 sama dengan Dana yang di simpan di Bank milik JEMAAT KIWI
B21: =B18+1 -> 4 | C21: Dianjurkan kepada Anggota Jemaat untuk melaksanakan Persembahan Terpadu Untuk membantu Operasional Jemaat.
B23: =B21+1 -> 5 | C23: Kami Ucapkan Trimakasih untuk Bendahara Jemaat sudah menggunakan WEB- System www.jlctreasury.com dalam membuat Laporan Keuangan Jemaat.
B25: =B23+1 -> 6 | C25: Kami ucapkan trimakasih kepada Bendahara Jemaat mengirimkan ( Transfer ) uang dan Laporan Keuangan seperti yang di tetapkan :
C26: Konferens DKI Jakarta tanggal 10 pada Bulan Berikutnya sampai di kantor Konferens. Kecuali Desember, Transfer Paling lambat Tanggal 31
C33: Hotland F Pasaribu, Church Auditor
C34: GMAHK Konferens Jakarta & Sekitarnya
